#VRML_SIM R2021a utf8
WorldInfo {
  basicTimeStep 16
  coordinateSystem "NUE"
  contactProperties [
    ContactProperties {
      material2 "slippy"
      coulombFriction [
        0
      ]
    }
    ContactProperties {
      material2 "block"
      coulombFriction [
        0.01
      ]
    }
    ContactProperties {
      material2 "robot"
    }
  ]
}
Viewpoint {
  orientation 0.4751332371403625 0.7345938215415756 0.4843762218745505 4.264723388114922
  position -1.1106046658024822 3.0149544069932936 -0.23075066507121456
}
Background {
  skyColor [
    0.15 0.45 1
  ]
}
Floor {
  size 2.4 2.4
  appearance Asphalt {
  }
}
Solid {
  translation 0.0013657 0.0249755 0.227424
  rotation -0.10571712175862764 0.9939685053046977 0.02916334393406797 5.847417805433601e-16
  children [
    Transform {
      translation 0 0.025 0
      children [
        Shape {
          appearance PBRAppearance {
            baseColor 1 0 0
            roughness 1
            metalness 0
            emissiveColor 1 0 0
          }
          geometry Sphere {
            radius 0.0025
          }
        }
        SpotLight {
          attenuation 0 0 12.47
          beamWidth 0.2
          color 1 0 0
          cutOffAngle 0.6
          direction 0 1 0
          intensity 0.01
          radius 0.5
        }
      ]
    }
    Solid {
      children [
        DEF BOX Shape {
          appearance PBRAppearance {
            roughness 1
            metalness 0
          }
          geometry Box {
            size 0.05 0.05 0.05
          }
        }
      ]
    }
  ]
  name "block"
  contactMaterial "block"
  boundingObject USE BOX
  physics DEF block_mass Physics {
    density -1
    mass 0.5
  }
}
Solid {
  translation 0.0013657 0.0249755 0.397424
  rotation -0.10571712175862764 0.9939685053046977 0.02916334393406797 5.847417805433601e-16
  children [
    Transform {
      translation 0 0.025 0
      children [
        Shape {
          appearance PBRAppearance {
            baseColor 1 0 0
            roughness 1
            metalness 0
            emissiveColor 1 0 0
          }
          geometry Sphere {
            radius 0.0025
          }
        }
        SpotLight {
          attenuation 0 0 12.47
          beamWidth 0.2
          color 1 0 0
          cutOffAngle 0.6
          direction 0 1 0
          intensity 0.01
          radius 0.5
        }
      ]
    }
    Solid {
      children [
        DEF BOX Shape {
          appearance PBRAppearance {
            roughness 1
            metalness 0
          }
          geometry Box {
            size 0.05 0.05 0.05
          }
        }
      ]
    }
  ]
  name "block(1)"
  contactMaterial "block"
  boundingObject USE BOX
  physics DEF block_mass Physics {
    density -1
    mass 0.5
  }
}
Solid {
  translation 0.0013657 0.0249755 0.297424
  rotation -0.10571712175862764 0.9939685053046977 0.02916334393406797 5.847417805433601e-16
  children [
    Transform {
      translation 0 0.025 0
      children [
        Shape {
          appearance PBRAppearance {
            baseColor 1 0 0
            roughness 1
            metalness 0
            emissiveColor 1 0 0
          }
          geometry Sphere {
            radius 0.0025
          }
        }
        SpotLight {
          attenuation 0 0 12.47
          beamWidth 0.2
          color 1 0 0
          cutOffAngle 0.6
          direction 0 1 0
          intensity 0.01
          radius 0.5
        }
      ]
    }
    Solid {
      children [
        DEF BOX Shape {
          appearance PBRAppearance {
            roughness 1
            metalness 0
          }
          geometry Box {
            size 0.05 0.05 0.05
          }
        }
      ]
    }
  ]
  name "block(2)"
  contactMaterial "block"
  boundingObject USE BOX
  physics DEF block_mass Physics {
    density -1
    mass 0.5
  }
}
Solid {
  translation 0.0013657 0.0249755 0.167424
  rotation -0.10571712175862764 0.9939685053046977 0.02916334393406797 5.847417805433601e-16
  children [
    Transform {
      translation 0 0.025 0
      children [
        Shape {
          appearance PBRAppearance {
            baseColor 1 0 0
            roughness 1
            metalness 0
            emissiveColor 1 0 0
          }
          geometry Sphere {
            radius 0.0025
          }
        }
        SpotLight {
          attenuation 0 0 12.47
          beamWidth 0.2
          color 1 0 0
          cutOffAngle 0.6
          direction 0 1 0
          intensity 0.01
          radius 0.5
        }
      ]
    }
    Solid {
      children [
        DEF BOX Shape {
          appearance PBRAppearance {
            roughness 1
            metalness 0
          }
          geometry Box {
            size 0.05 0.05 0.05
          }
        }
      ]
    }
  ]
  name "block(3)"
  contactMaterial "block"
  boundingObject USE BOX
  physics DEF block_mass Physics {
    density -1
    mass 0.5
  }
}
DEF Floor_colour Solid {
  translation 0 0.0001 0.4
  children [
    Shape {
      appearance PBRAppearance {
        baseColor 1 0 0
      }
      geometry Plane {
        size 0.4 0.4
      }
    }
  ]
  name "solid(6)"
}
DEF Floor_colour Solid {
  translation 0 0.0001 -0.4
  children [
    Shape {
      appearance PBRAppearance {
        baseColor 0 1 0
      }
      geometry Plane {
        size 0.4 0.4
      }
    }
  ]
  name "solid(5)"
}
DEF WALL_1 Solid {
  translation 1.2 0.05 0
  children [
    DEF WALL_SHAPE Shape {
      appearance PBRAppearance {
        baseColor 0 0.333333 0
        roughness 1
        metalness 0
      }
      geometry Box {
        size 0.02 0.1 2.38
      }
    }
  ]
  boundingObject USE WALL_SHAPE
}
DEF WALL_2 Solid {
  translation -1.2 0.05 0
  children [
    USE WALL_SHAPE
  ]
  name "solid(1)"
  boundingObject USE WALL_SHAPE
}
DEF WALL_3 Solid {
  translation 0 0.05 -1.2
  rotation 0 1 0 1.5708
  children [
    USE WALL_SHAPE
  ]
  name "solid(2)"
  boundingObject USE WALL_SHAPE
}
DEF WALL_4 Solid {
  translation 0 0.05 1.2
  rotation 0 1 0 1.5708
  children [
    USE WALL_SHAPE
  ]
  name "solid(3)"
  boundingObject USE WALL_SHAPE
}
TexturedBackgroundLight {
  texture "empty_office"
}
Robot {
  translation 0 0.0384 -0.85
  children [
    DistanceSensor {
      translation 0 0 0.12
      name "ultrasonic"
      lookupTable [
        0 0 0
        0.15 0.15 0.004
        0.3 0.3 0.005
        0.45 0.45 0.005
        0.6 0.6 0.006
        0.75 0.75 0.006
        0.9 0.9 0.007
        1.05 1.05 0.007
        1.2 1.2 0.008
        1.35 1.35 0.009
        1.5 1.5 0.01
      ]
      type "sonar"
      aperture 0.5235987756
    }
    Display {
      name "map"
      width 256
      height 256
    }
    Compass {
      yAxis FALSE
    }
    GPS {
    }
    Camera {
      translation 0 0 0.1
      width 1
      height 1
    }
    Solid {
      translation 0 -0.03 0
      children [
        Shape {
          geometry DEF CASTOR_BALL Sphere {
            radius 0.01
          }
        }
      ]
      name "solid(2)"
      contactMaterial "slippy"
      boundingObject USE CASTOR_BALL
      physics Physics {
      }
    }
    DEF BODY Shape {
      appearance PBRAppearance {
        baseColor 1 0 0
        roughness 1
        metalness 0
      }
      geometry Box {
        size 0.1 0.05 0.2
      }
    }
    DEF WHEEL1 HingeJoint {
      jointParameters HingeJointParameters {
        position 4521.674876353648
        anchor 0.06 0 0.05
      }
      device [
        RotationalMotor {
          name "wheel1"
          maxVelocity 20
          maxTorque 0.4
        }
      ]
      endPoint Solid {
        translation 0.06000337936200241 -4.3119469605215794e-06 0.0500014789810879
        rotation -0.6698676394462081 0.6695757803175358 0.3208513986800243 2.5193515997861793
        children [
          DEF WHEEL Shape {
            appearance PBRAppearance {
              baseColor 0.305882 0.898039 0.25098
              roughness 1
              metalness 0
            }
            geometry Cylinder {
              height 0.02
              radius 0.04
              subdivision 24
            }
          }
        ]
        boundingObject USE WHEEL
        physics Physics {
        }
      }
    }
    DEF WHEEL2 HingeJoint {
      jointParameters HingeJointParameters {
        position 994.2560276737038
        anchor -0.06 0 0.05
      }
      device [
        RotationalMotor {
          name "wheel2"
          maxVelocity 20
          maxTorque 0.4
        }
      ]
      endPoint Solid {
        translation -0.06000319490125795 -1.798344865592334e-06 0.05000190345208235
        rotation 0.5595885971541441 -0.5602562523668286 0.6107155914326517 2.045867787590605
        children [
          USE WHEEL
        ]
        name "solid(1)"
        boundingObject USE WHEEL
        physics Physics {
        }
      }
    }
    DEF DS_RIGHT DistanceSensor {
      translation -0.03 0 0.1
      rotation 0 1 0 -1.87079
      children [
        Shape {
          appearance PBRAppearance {
            baseColor 0.184314 0.596078 0.847059
            roughness 1
            metalness 0
          }
          geometry Box {
            size 0.01 0.01 0.01
          }
        }
      ]
      name "ds_right"
    }
    DEF DS_LEFT DistanceSensor {
      translation 0.03 0 0.1
      rotation 0 1 0 -1.27079
      children [
        Shape {
          appearance PBRAppearance {
            baseColor 0.184314 0.596078 0.847059
            roughness 1
            metalness 0
          }
          geometry Box {
            size 0.01 0.01 0.01
          }
        }
      ]
      name "ds_left"
    }
  ]
  contactMaterial ""
  boundingObject USE BODY
  physics Physics {
    density -1
    mass 1
  }
  controller "foward"
}
