#VRML_SIM R2021a utf8
WorldInfo {
  basicTimeStep 16
  coordinateSystem "NUE"
  contactProperties [
    ContactProperties {
      material2 "slippy"
      coulombFriction [
        0
      ]
    }
    ContactProperties {
      material2 "block"
      coulombFriction [
        0.01
      ]
    }
  ]
}
Viewpoint {
  orientation 0.33051396750456663 0.9000811714236767 0.28392675487345687 4.5556931387652515
  position -5.000892669168775 3.4606632788530014 -0.49517899893316164
}
Background {
  skyColor [
    0.15 0.45 1
  ]
}
Floor {
  size 2.4 2.4
  appearance Asphalt {
  }
}
target {
  translation -0.639 0.024975475000000004 0.42
  rotation -0.016204396117765505 0.9891755348723316 -0.1458395651272147 2.630925818835205e-16
  name "target(9)"
}
target {
  translation 0.977 0.024975475000000004 0.6057
  rotation -0.10571712175862764 0.9939685053046977 0.02916334393406797 5.847417805433601e-16
  name "target(8)"
}
target {
  translation 0.6867 0.024975475000000004 0.5714
  rotation -0.10571712175862764 0.9939685053046977 0.02916334393406797 5.847417805433601e-16
  name "target(7)"
}
target {
  translation 1.0798 0.024975475 -0.2533
  rotation 0.16179674612872036 0.8967744804020208 0.4118462628722566 1.4492201382898966e-16
  name "target(6)"
}
target {
  translation 0.3797688366042708 0.024975475000000004 0.3724416706054075
  rotation -3.6850022457837276e-17 1 -1.1383050213501675e-17 0.8770524261160295
  colour 0 1 0
  name "target(5)"
}
target {
  translation -1.0911 0.024975475 -0.7727
  rotation 0.027187739186451905 0.997615376597055 -0.0634380580964271 -4.704241553937696e-16
  colour 0 1 0
  name "target(1)"
}
target {
  translation 0.8205 0.024975475000000004 0.4842
  rotation -0.08716996035580256 0.9961619344504159 0.007924541852560103 -5.379814372613734e-16
  colour 0 1 0
  name "target(2)"
}
target {
  translation 1.0199 0.024975475000000004 -1.1002
  rotation -0.7516595996081347 0.3124849260239192 -0.5808278723724994 -6.238970484152511e-17
  colour 0 1 0
  name "target(3)"
}
DEF Floor_colour Solid {
  translation 0 0.0001 0.4
  children [
    Shape {
      appearance PBRAppearance {
        baseColor 1 0 0
      }
      geometry Plane {
        size 0.4 0.4
      }
    }
  ]
  name "solid(6)"
}
DEF Floor_colour Solid {
  translation 0 0.0001 -0.4
  children [
    Shape {
      appearance PBRAppearance {
        baseColor 0 1 0
      }
      geometry Plane {
        size 0.4 0.4
      }
    }
  ]
  name "solid(5)"
}
DEF WALL_1 Solid {
  translation 1.2 0.05 0
  children [
    DEF WALL_SHAPE Shape {
      appearance PBRAppearance {
        baseColor 0 0.333333 0
        roughness 1
        metalness 0
      }
      geometry Box {
        size 0.02 0.1 2.38
      }
    }
  ]
  boundingObject USE WALL_SHAPE
}
DEF WALL_2 Solid {
  translation -1.2 0.05 0
  children [
    USE WALL_SHAPE
  ]
  name "solid(1)"
  boundingObject USE WALL_SHAPE
}
DEF WALL_3 Solid {
  translation 0 0.05 -1.2
  rotation 0 1 0 1.5708
  children [
    USE WALL_SHAPE
  ]
  name "solid(2)"
  boundingObject USE WALL_SHAPE
}
DEF WALL_4 Solid {
  translation 0 0.05 1.2
  rotation 0 1 0 1.5708
  children [
    USE WALL_SHAPE
  ]
  name "solid(3)"
  boundingObject USE WALL_SHAPE
}
TexturedBackgroundLight {
  texture "empty_office"
}
Robot {
  translation -0.22489645227164576 0.03920094945516683 -0.3636701590082667
  rotation -0.0063769287004701 -0.9999507024317766 -0.007611010875410823 1.7479964575638762
  children [
    DistanceSensor {
      rotation 0 1 0 -1.570796327
      name "ir_long"
      lookupTable [
        0 0 0
        0.1 2.31 0.0216
        0.15 2.75 0.0182
        0.2 2.53 0.0198
        0.3 1.98 0.0253
        0.4 1.54 0.0325
        0.5 1.23 0.0407
        0.6 1.05 0.0476
        0.7 0.9 0.0556
        0.8 0.81 0.0617
        0.9 0.72 0.0694
        1 0.65 0.0769
        1.1 0.6 0.0833
        1.2 0.55 0.0909
        1.3 0.52 0.0962
        1.4 0.48 0.1042
        1.5 0.45 0.1111
      ]
      type "infra-red"
      aperture 0.05235987756
    }
    DistanceSensor {
      rotation 0 1 0 -1.570796327
      name "ultrasonic"
      lookupTable [
        0 0 0
        0.15 0.15 0.004
        0.3 0.3 0.005
        0.45 0.45 0.005
        0.6 0.6 0.006
        0.75 0.75 0.006
        0.9 0.9 0.007
        1.05 1.05 0.007
        1.2 1.2 0.008
        1.35 1.35 0.009
        1.5 1.5 0.01
      ]
      type "sonar"
      aperture 0.5235987756
    }
    Display {
      name "map"
      width 256
      height 256
    }
    Compass {
      yAxis FALSE
    }
    GPS {
    }
    Camera {
      translation 0 0 0.1
      width 1
      height 1
    }
    Solid {
      translation 0 -0.03 0
      children [
        Shape {
          geometry DEF CASTOR_BALL Sphere {
            radius 0.01
          }
        }
      ]
      name "solid(2)"
      contactMaterial "slippy"
      boundingObject USE CASTOR_BALL
      physics Physics {
      }
    }
    DEF BODY Shape {
      appearance PBRAppearance {
        baseColor 1 0 0
        roughness 1
        metalness 0
      }
      geometry Box {
        size 0.1 0.05 0.2
      }
    }
    DEF WHEEL1 HingeJoint {
      jointParameters HingeJointParameters {
        position 4521.674876353648
        anchor 0.06 0 0.05
      }
      device [
        RotationalMotor {
          name "wheel1"
          maxTorque 100
        }
      ]
      endPoint Solid {
        translation 0.06000000000005251 -8.131971158399085e-07 0.050000433082926794
        rotation 0.6674079068382102 -0.6674103586178619 -0.33034845103226357 3.779713983310502
        children [
          DEF WHEEL Shape {
            appearance PBRAppearance {
              baseColor 0.305882 0.898039 0.25098
              roughness 1
              metalness 0
            }
            geometry Cylinder {
              height 0.02
              radius 0.04
              subdivision 24
            }
          }
        ]
        boundingObject USE WHEEL
        physics Physics {
        }
        linearVelocity -0.07597630181420084 2.193257384228103e-08 -0.013419957567549169
        angularVelocity -0.3478420333809331 -0.286510658524471 1.9695104958895313
      }
    }
    DEF WHEEL2 HingeJoint {
      jointParameters HingeJointParameters {
        position 994.2560276737038
        anchor -0.06 0 0.05
      }
      device [
        RotationalMotor {
          name "wheel2"
          maxTorque 100
        }
      ]
      endPoint Solid {
        translation -0.05999999999986491 8.9965680693241e-07 0.05000024230412242
        rotation -0.5651530740766907 0.5651551503244598 -0.6010005481889377 4.223899155271772
        children [
          USE WHEEL
        ]
        name "solid(1)"
        boundingObject USE WHEEL
        physics Physics {
        }
        linearVelocity -0.04220264764215751 1.7312865946774472e-08 -0.007453346252283722
        angularVelocity -0.17396466396003177 -0.2859877455608168 0.9847408719499786
      }
    }
    DEF DS_RIGHT DistanceSensor {
      translation -0.03 0 0.1
      rotation 0 1 0 -1.87079
      children [
        Shape {
          appearance PBRAppearance {
            baseColor 0.184314 0.596078 0.847059
            roughness 1
            metalness 0
          }
          geometry Box {
            size 0.01 0.01 0.01
          }
        }
      ]
      name "ds_right"
    }
    DEF DS_LEFT DistanceSensor {
      translation 0.03 0 0.1
      rotation 0 1 0 -1.27079
      children [
        Shape {
          appearance PBRAppearance {
            baseColor 0.184314 0.596078 0.847059
            roughness 1
            metalness 0
          }
          geometry Box {
            size 0.01 0.01 0.01
          }
        }
      ]
      name "ds_left"
    }
  ]
  boundingObject USE BODY
  physics Physics {
    density -1
    mass 1
  }
  controller "<extern>"
  linearVelocity -0.061575803816178803 -8.057150858680793e-08 0.003634728333032949
  angularVelocity -3.4842749293080174e-06 -0.2858148192234031 -1.4321027616922836e-05
}
