#VRML_SIM R2021a utf8
WorldInfo {
  basicTimeStep 4
  coordinateSystem "NUE"
  contactProperties [
    ContactProperties {
      material2 "slippy"
      coulombFriction [
        0
      ]
    }
    ContactProperties {
      material2 "block"
      coulombFriction [
        0.1
      ]
      forceDependentSlip [
        0, 0
      ]
    }
    ContactProperties {
      material2 "robot"
    }
  ]
}
Viewpoint {
  orientation -0.6013248986366548 0.5232502214613423 0.6038357160853215 2.026866415140069
  position -0.15003382431660586 1.6261700156601027 0.9017676620196033
}
Background {
  skyColor [
    0.15 0.45 1
  ]
}
Floor {
  size 2.4 2.4
  appearance Asphalt {
  }
}
DEF Floor_colour Solid {
  translation 0 0.0001 0.4
  children [
    Shape {
      appearance PBRAppearance {
        baseColor 1 0 0
      }
      geometry Plane {
        size 0.4 0.4
      }
    }
  ]
  name "solid(6)"
}
DEF Floor_colour Solid {
  translation 0 0.0001 -0.4
  children [
    Shape {
      appearance PBRAppearance {
        baseColor 0 1 0
      }
      geometry Plane {
        size 0.4 0.4
      }
    }
  ]
  name "solid(5)"
}
DEF WALL_1 Solid {
  translation 1.2 0.05 0
  children [
    DEF WALL_SHAPE Shape {
      appearance PBRAppearance {
        baseColor 0 0.333333 0
        roughness 1
        metalness 0
      }
      geometry Box {
        size 0.02 0.1 2.38
      }
    }
  ]
  boundingObject USE WALL_SHAPE
}
DEF WALL_3 Solid {
  translation 0 0.05 -1.2
  rotation 0 1 0 1.5708
  children [
    USE WALL_SHAPE
  ]
  name "solid(2)"
  boundingObject USE WALL_SHAPE
}
DEF WALL_4 Solid {
  translation 0 0.05 1.2
  rotation 0 1 0 1.5708
  children [
    USE WALL_SHAPE
  ]
  name "solid(3)"
  boundingObject USE WALL_SHAPE
}
TexturedBackgroundLight {
  texture "empty_office"
}
Solid {
  translation -0.03 0.03 0.61
  children [
    Transform {
      translation 0 0.025 0
      children [
        Shape {
          appearance PBRAppearance {
            baseColor 1 0 0
            roughness 1
            metalness 0
            emissiveColor 1 0 0
          }
          geometry Sphere {
            radius 0.0025
          }
        }
        SpotLight {
          attenuation 0 0 12.47
          beamWidth 0.2
          color 1 0 0
          cutOffAngle 0.6
          direction 0 1 0
          intensity 0.01
          radius 0.5
        }
      ]
    }
    Solid {
      children [
        DEF BOX Shape {
          appearance PBRAppearance {
            roughness 1
            metalness 0
          }
          geometry Box {
            size 0.05 0.05 0.05
          }
        }
      ]
    }
  ]
  name "target(3)"
  contactMaterial "block"
  boundingObject USE BOX
  physics Physics {
  }
}
Solid {
  translation -0.17 0.05 0.8
  children [
    Transform {
      translation 0 0.025 0
      children [
        Shape {
          appearance PBRAppearance {
            baseColor 1 0 0
            roughness 1
            metalness 0
            emissiveColor 1 0 0
          }
          geometry Sphere {
            radius 0.0025
          }
        }
        SpotLight {
          attenuation 0 0 12.47
          beamWidth 0.2
          color 1 0 0
          cutOffAngle 0.6
          direction 0 1 0
          intensity 0.01
          radius 0.5
        }
      ]
    }
    Solid {
      children [
        DEF BOX Shape {
          appearance PBRAppearance {
            roughness 1
            metalness 0
          }
          geometry Box {
            size 0.05 0.05 0.05
          }
        }
      ]
    }
  ]
  name "target(1)"
  contactMaterial "block"
  boundingObject USE BOX
  physics Physics {
  }
}
Solid {
  translation -0.148787 0.05 0.877781
  rotation 0 1 0 0.785398
  children [
    Transform {
      translation 0 0.025 0
      children [
        Shape {
          appearance PBRAppearance {
            baseColor 1 0 0
            roughness 1
            metalness 0
            emissiveColor 1 0 0
          }
          geometry Sphere {
            radius 0.0025
          }
        }
        SpotLight {
          attenuation 0 0 12.47
          beamWidth 0.2
          color 1 0 0
          cutOffAngle 0.6
          direction 0 1 0
          intensity 0.01
          radius 0.5
        }
      ]
    }
    Solid {
      children [
        DEF BOX Shape {
          appearance PBRAppearance {
            roughness 1
            metalness 0
          }
          geometry Box {
            size 0.05 0.05 0.05
          }
        }
      ]
    }
  ]
  name "target(5)"
  contactMaterial "block"
  boundingObject USE BOX
  physics Physics {
  }
}
Solid {
  translation -0.06 0.05 0.92
  children [
    Transform {
      translation 0 0.025 0
      children [
        Shape {
          appearance PBRAppearance {
            baseColor 1 0 0
            roughness 1
            metalness 0
            emissiveColor 1 0 0
          }
          geometry Sphere {
            radius 0.0025
          }
        }
        SpotLight {
          attenuation 0 0 12.47
          beamWidth 0.2
          color 1 0 0
          cutOffAngle 0.6
          direction 0 1 0
          intensity 0.01
          radius 0.5
        }
      ]
    }
    Solid {
      children [
        DEF BOX Shape {
          appearance PBRAppearance {
            roughness 1
            metalness 0
          }
          geometry Box {
            size 0.05 0.05 0.05
          }
        }
      ]
    }
  ]
  name "target(4)"
  contactMaterial "block"
  boundingObject USE BOX
  physics Physics {
  }
}
Robot {
  translation -0.03 0.035 0.76
  children [
    DistanceSensor {
      translation 0 0 0.075
      rotation 0 1 0 -1.570796327
      name "ir_long"
      lookupTable [
        0 0 0
        0.1 2.31 0.0072
        0.15 2.75 0.0061
        0.2 2.53 0.0066
        0.3 1.98 0.0084
        0.4 1.54 0.0108
        0.5 1.23 0.0136
        0.6 1.05 0.0159
        0.7 0.9 0.0185
        0.8 0.81 0.0206
        0.9 0.72 0.0231
        1 0.65 0.0256
        1.1 0.6 0.0278
        1.2 0.55 0.0303
        1.3 0.52 0.0321
        1.4 0.48 0.0347
        1.5 0.45 0.037
      ]
      type "laser"
      aperture 0.05235987756
    }
    DistanceSensor {
      translation -0.0225 -0.02 0.075
      rotation 0 1 0 -1.745
      name "ultrasonic_right"
      lookupTable [
        0 0 0
        0.1 0.1 0.01667
        0.2 0.2 0.00833
        0.3 0.3 0.00556
        0.4 0.4 0.00417
        0.5 0.5 0.00333
        0.6 0.6 0.00278
        0.7 0.7 0.00238
        0.8 0.8 0.00208
        0.9 0.9 0.00185
        1 1 0.00167
      ]
      type "sonar"
      numberOfRays 20
      aperture 0.5235987756
    }
    DistanceSensor {
      translation 0.0225 -0.02 0.075
      rotation 0 1 0 -1.396
      name "ultrasonic_left"
      lookupTable [
        0 0 0
        0.1 0.1 0.01667
        0.2 0.2 0.00833
        0.3 0.3 0.00556
        0.4 0.4 0.00417
        0.5 0.5 0.00333
        0.6 0.6 0.00278
        0.7 0.7 0.00238
        0.8 0.8 0.00208
        0.9 0.9 0.00185
        1 1 0.00167
      ]
      type "sonar"
      numberOfRays 20
      aperture 0.5235987756
    }
    DEF GATE HingeJoint {
      jointParameters HingeJointParameters {
        position 5.616075030873274e-07
        axis -1 0 0
        anchor -0.075 0 0.075
      }
      device [
        RotationalMotor {
          name "gate"
        }
      ]
      endPoint Solid {
        translation -0.07500331043919162 5.7986316944162475e-09 0.15000659910768502
        rotation 0.5773470444485193 0.577352044030533 0.5773517190762706 2.094399351658308
        children [
          DEF GATE_SHAPE Shape {
            geometry Cylinder {
              height 0.15
              radius 0.005
            }
          }
        ]
        name "solid(2)"
        boundingObject USE GATE_SHAPE
        physics Physics {
          density -1
          mass 0.01
        }
      }
    }
    DEF RIGHT_WHEEL HingeJoint {
      jointParameters HingeJointParameters {
        anchor 0.09 0.015 0
      }
      device [
        RotationalMotor {
          name "wheel2"
        }
      ]
      endPoint DEF WHEEL2 Solid {
        translation 0.09 0.015001 0
        rotation -3.7861143243286335e-05 -3.026546465724968e-05 0.9999999988252678 4.712381360370644
        children [
          DEF WHEEL Shape {
            geometry Cylinder {
              height 0.01
              radius 0.05
            }
          }
        ]
        name "solid(1)"
        boundingObject USE WHEEL
        physics DEF WHEEL_PH Physics {
        }
      }
    }
    DEF BODY Group {
      children [
        DEF FENCE2 Transform {
          translation -0.075 0 0.225
          rotation -0.5773479358540498 0.5773509358537164 0.5773519358536053 2.0944
          children [
            DEF SCOOP_2 Shape {
              geometry Extrusion {
                crossSection [
                  -0.005 -0.005
                  -0.005 0.005
                  0.005 0.005
                  0.005 -0.005
                  -0.005 -0.005
                ]
                spine [
                  0 0 0
                  0.01 0.0359 0
                  0.02 0.04989 0
                  0.03 0.06 0
                  0.04 0.068 0
                  0.05 0.0745 0
                  0.06 0.08 0
                  0.07 0.0846 0
                  0.08 0.0884 0
                  0.09 0.0916 0
                  0.1 0.0943 0
                  0.11 0.0964 0
                  0.12 0.098 0
                  0.13 0.0991 0
                  0.14 0.0998 0
                  0.15 0.1 0
                ]
              }
            }
          ]
        }
        DEF FENCE1 Transform {
          translation -0.075 0 -0.075
          rotation 0.5773509358560258 -0.577349935856137 0.577349935856137 2.0944
          children [
            DEF SCOOP_2 Shape {
              geometry Extrusion {
                crossSection [
                  -0.005 -0.005
                  -0.005 0.005
                  0.005 0.005
                  0.005 -0.005
                  -0.005 -0.005
                ]
                spine [
                  0 0 0
                  0 0.1 0
                  0.01 0.1 0
                  0.15 0.1 0
                ]
              }
            }
          ]
        }
        DEF SLIPPER Transform {
          translation -0.175 -0.0175 0.055
          children [
            DEF CASTER Shape {
              geometry Sphere {
                radius 0.0175
              }
            }
          ]
        }
        DEF MAIN_BODY Shape {
          geometry Box {
            size 0.15 0.05 0.15
          }
        }
      ]
    }
    DEF LEFT_WHEEL HingeJoint {
      jointParameters HingeJointParameters {
        anchor -0.09 0.015 0
      }
      device [
        RotationalMotor {
          name "wheel1"
        }
      ]
      endPoint DEF WHEEL1 Solid {
        translation -0.09000159771559374 0.015000133584730499 1.0597795415029146e-06
        rotation 3.86551247391617e-05 4.768814104523109e-05 0.9999999981158113 4.7123919405676125
        children [
          DEF WHEEL Shape {
            geometry Cylinder {
              height 0.01
              radius 0.05
            }
          }
        ]
        boundingObject USE WHEEL
        physics DEF WHEEL_PH Physics {
        }
      }
    }
  ]
  contactMaterial "slippy"
  boundingObject Group {
    children [
      USE SLIPPER
      USE FENCE2
      USE FENCE1
      USE MAIN_BODY
    ]
  }
  physics Physics {
    density 2000
    centerOfMass [
      0 0 0
    ]
  }
  controller "foward"
}
