#VRML_SIM R2021a utf8
WorldInfo {
  basicTimeStep 4
  coordinateSystem "NUE"
  contactProperties [
    ContactProperties {
      material2 "slippy"
      coulombFriction [
        0
      ]
    }
    ContactProperties {
      material2 "block"
      coulombFriction [
        0.1
      ]
      forceDependentSlip [
        0, 0
      ]
    }
    ContactProperties {
      material2 "robot"
    }
  ]
}
Viewpoint {
  orientation -0.3206811032691578 -0.8299824823358699 -0.45639096071423596 2.1174444699140365
  position -0.7270197805408002 1.8027556507070936 0.32759210717584963
}
Background {
  skyColor [
    0.15 0.45 1
  ]
}
Floor {
  size 2.4 2.4
  appearance Asphalt {
  }
}
DEF Floor_colour Solid {
  translation 0 0.0001 0.4
  children [
    Shape {
      appearance PBRAppearance {
        baseColor 1 0 0
      }
      geometry Plane {
        size 0.4 0.4
      }
    }
  ]
  name "solid(6)"
}
DEF Floor_colour Solid {
  translation 0 0.0001 -0.4
  children [
    Shape {
      appearance PBRAppearance {
        baseColor 0 1 0
      }
      geometry Plane {
        size 0.4 0.4
      }
    }
  ]
  name "solid(5)"
}
DEF WALL_1 Solid {
  translation 1.2 0.05 0
  children [
    DEF WALL_SHAPE Shape {
      appearance PBRAppearance {
        baseColor 0 0.333333 0
        roughness 1
        metalness 0
      }
      geometry Box {
        size 0.02 0.1 2.38
      }
    }
  ]
  boundingObject USE WALL_SHAPE
}
DEF WALL_3 Solid {
  translation 0 0.05 -1.2
  rotation 0 1 0 1.5708
  children [
    USE WALL_SHAPE
  ]
  name "solid(2)"
  boundingObject USE WALL_SHAPE
}
DEF WALL_4 Solid {
  translation 0 0.05 1.2
  rotation 0 1 0 1.5708
  children [
    USE WALL_SHAPE
  ]
  name "solid(3)"
  boundingObject USE WALL_SHAPE
}
TexturedBackgroundLight {
  texture "empty_office"
}
Solid {
  translation 0 0.05 0.89
  children [
    Transform {
      translation 0 0.025 0
      children [
        Shape {
          appearance PBRAppearance {
            baseColor 1 0 0
            roughness 1
            metalness 0
            emissiveColor 1 0 0
          }
          geometry Sphere {
            radius 0.0025
          }
        }
        SpotLight {
          attenuation 0 0 12.47
          beamWidth 0.2
          color 1 0 0
          cutOffAngle 0.6
          direction 0 1 0
          intensity 0.01
          radius 0.5
        }
      ]
    }
    Solid {
      children [
        DEF BOX Shape {
          appearance PBRAppearance {
            roughness 1
            metalness 0
          }
          geometry Box {
            size 0.05 0.05 0.05
          }
        }
      ]
    }
  ]
  name "target(2)"
  contactMaterial "block"
  boundingObject USE BOX
  physics Physics {
  }
}
Solid {
  translation -0.03 0.03 0.61
  children [
    Transform {
      translation 0 0.025 0
      children [
        Shape {
          appearance PBRAppearance {
            baseColor 1 0 0
            roughness 1
            metalness 0
            emissiveColor 1 0 0
          }
          geometry Sphere {
            radius 0.0025
          }
        }
        SpotLight {
          attenuation 0 0 12.47
          beamWidth 0.2
          color 1 0 0
          cutOffAngle 0.6
          direction 0 1 0
          intensity 0.01
          radius 0.5
        }
      ]
    }
    Solid {
      children [
        DEF BOX Shape {
          appearance PBRAppearance {
            roughness 1
            metalness 0
          }
          geometry Box {
            size 0.05 0.05 0.05
          }
        }
      ]
    }
  ]
  name "target(3)"
  contactMaterial "block"
  boundingObject USE BOX
  physics Physics {
  }
}
Solid {
  translation -0.18 0.05 0.79
  children [
    Transform {
      translation 0 0.025 0
      children [
        Shape {
          appearance PBRAppearance {
            baseColor 1 0 0
            roughness 1
            metalness 0
            emissiveColor 1 0 0
          }
          geometry Sphere {
            radius 0.0025
          }
        }
        SpotLight {
          attenuation 0 0 12.47
          beamWidth 0.2
          color 1 0 0
          cutOffAngle 0.6
          direction 0 1 0
          intensity 0.01
          radius 0.5
        }
      ]
    }
    Solid {
      children [
        DEF BOX Shape {
          appearance PBRAppearance {
            roughness 1
            metalness 0
          }
          geometry Box {
            size 0.05 0.05 0.05
          }
        }
      ]
    }
  ]
  name "target(1)"
  contactMaterial "block"
  boundingObject USE BOX
  physics Physics {
  }
}
Solid {
  translation -0.16 0.05 0.67
  children [
    Transform {
      translation 0 0.025 0
      children [
        Shape {
          appearance PBRAppearance {
            baseColor 1 0 0
            roughness 1
            metalness 0
            emissiveColor 1 0 0
          }
          geometry Sphere {
            radius 0.0025
          }
        }
        SpotLight {
          attenuation 0 0 12.47
          beamWidth 0.2
          color 1 0 0
          cutOffAngle 0.6
          direction 0 1 0
          intensity 0.01
          radius 0.5
        }
      ]
    }
    Solid {
      children [
        DEF BOX Shape {
          appearance PBRAppearance {
            roughness 1
            metalness 0
          }
          geometry Box {
            size 0.05 0.05 0.05
          }
        }
      ]
    }
  ]
  name "target(4)"
  contactMaterial "block"
  boundingObject USE BOX
  physics Physics {
  }
}
Robot {
  translation -0.03 0.035 0.76
  children [
    DEF GATE HingeJoint {
      jointParameters HingeJointParameters {
        position 5.616075030873274e-07
        axis -1 0 0
        anchor -0.075 0 0.075
      }
      device [
        RotationalMotor {
          name "gate"
        }
      ]
      endPoint Solid {
        translation -0.075 8.42411254630814e-08 0.14999999999995267
        rotation 0.5773470439332342 0.5773520439336263 0.5773517196884583 2.094399351512359
        children [
          DEF GATE_SHAPE Shape {
            geometry Cylinder {
              height 0.15
              radius 0.005
            }
          }
        ]
        name "solid(2)"
        boundingObject USE GATE_SHAPE
        physics Physics {
          density -1
          mass 0.01
        }
      }
    }
    DEF RIGHT_WHEEL HingeJoint {
      jointParameters HingeJointParameters {
        anchor 0.075 0.015 0
      }
      device [
        RotationalMotor {
          name "wheel2"
        }
      ]
      endPoint DEF WHEEL2 Solid {
        translation 0.08 0.015 0
        rotation 0 0 -0.9999999999999999 1.5707953071795862
        children [
          DEF WHEEL Shape {
            geometry Cylinder {
              height 0.01
              radius 0.05
            }
          }
        ]
        name "solid(1)"
        boundingObject USE WHEEL
        physics DEF WHEEL_PH Physics {
        }
      }
    }
    DEF BODY Group {
      children [
        DEF FENCE2 Transform {
          translation -0.075 0 0.225
          rotation -0.5773479358540498 0.5773509358537164 0.5773519358536053 2.0944
          children [
            DEF SCOOP_2 Shape {
              geometry Extrusion {
                crossSection [
                  -0.005 -0.005
                  -0.005 0.005
                  0.005 0.005
                  0.005 -0.005
                  -0.005 -0.005
                ]
                spine [
                  0 0 0
                  0.01 0.0359 0
                  0.02 0.04989 0
                  0.03 0.06 0
                  0.04 0.068 0
                  0.05 0.0745 0
                  0.06 0.08 0
                  0.07 0.0846 0
                  0.08 0.0884 0
                  0.09 0.0916 0
                  0.1 0.0943 0
                  0.11 0.0964 0
                  0.12 0.098 0
                  0.13 0.0991 0
                  0.14 0.0998 0
                  0.15 0.1 0
                ]
              }
            }
          ]
        }
        DEF FENCE1 Transform {
          translation -0.075 0 -0.075
          rotation 0.5773509358560258 -0.577349935856137 0.577349935856137 2.0944
          children [
            DEF SCOOP_2 Shape {
              geometry Extrusion {
                crossSection [
                  -0.005 -0.005
                  -0.005 0.005
                  0.005 0.005
                  0.005 -0.005
                  -0.005 -0.005
                ]
                spine [
                  0 0 0
                  0 0.1 0
                  0.01 0.1 0
                  0.15 0.1 0
                ]
              }
            }
          ]
        }
        DEF SLIPPER Transform {
          translation -0.175 -0.02 0.075
          children [
            DEF CASTER Shape {
              geometry Sphere {
                radius 0.015
              }
            }
          ]
        }
        DEF MAIN_BODY Shape {
          geometry Box {
            size 0.15 0.05 0.15
          }
        }
      ]
    }
    DEF LEFT_WHEEL HingeJoint {
      jointParameters HingeJointParameters {
        anchor -0.075 0.015 0
      }
      device [
        RotationalMotor {
          name "wheel1"
        }
      ]
      endPoint DEF WHEEL1 Solid {
        translation -0.08 0.015 0
        rotation 0 0 -0.9999999999999999 1.5707953071795862
        children [
          DEF WHEEL Shape {
            geometry Cylinder {
              height 0.01
              radius 0.05
            }
          }
        ]
        boundingObject USE WHEEL
        physics DEF WHEEL_PH Physics {
        }
      }
    }
  ]
  contactMaterial "slippy"
  boundingObject Group {
    children [
      USE SLIPPER
      USE FENCE2
      USE FENCE1
      USE MAIN_BODY
    ]
  }
  physics Physics {
    density 2000
  }
  controller "foward"
}
